<?xml version="1.0"?>
<robot name="gae_vehicle" xmlns:xacro="http://www.ros.org/wiki/xacro">
  
  <xacro:include filename="$(find velodyne_description)/urdf/VLP-16.urdf.xacro"/>
  <xacro:include filename="$(find gae_vehicle_description)/urdf/zed2.xacro"/>

  <xacro:property name="half_front_track_width" value="0.51" />
  <xacro:property name="half_rear_track_width" value="0.51" />
  <xacro:property name="half_wheelbase" value="0.74" />

  <xacro:property name="wheel_radius" value="0.30" />
  <xacro:property name="wheel_thickness" value="0.10" />
  <xacro:property name="wheel_mass" value="90.0" />

  <xacro:property name="body_mass" value="4000.0" />
  <xacro:property name="body_width" value="${2*half_rear_track_width}" />
  <xacro:property name="body_depth" value="${2*half_wheelbase + 0.8}" />
  <xacro:property name="body_length" value="0.6" />

  <xacro:arg name="pub_tf" default="true" />

  <gazebo>
    <!-- Simulated vehicle interface -->
    <plugin name="gae_sim_interface_plugin" filename="libgae_sim_interface_plugin.so" >
      <pub_tf>$(arg pub_tf)</pub_tf>
      <tf_freq>100.0</tf_freq>
    </plugin>

    <!-- Publish current joint angles -->
    <plugin name="joint_state_publisher" filename="libgazebo_ros_joint_state_publisher.so">
        <joint_name>steer_fl_joint</joint_name>
        <joint_name>steer_fr_joint</joint_name>
        <joint_name>wheel_fl_joint</joint_name>
        <joint_name>wheel_fr_joint</joint_name>
        <joint_name>wheel_rl_joint</joint_name>
        <joint_name>wheel_rr_joint</joint_name>
        <update_rate>100</update_rate>
    </plugin>
  </gazebo>

  <xacro:macro name="rear_wheel" params="name x y z flip" >
    <link name="wheel_${name}" >
      <visual>
        <origin xyz="0 0 0" rpy="1.57079632679 ${flip * 3.1415926535} 0" />
        <geometry>
          <mesh filename="file://$(find gae_vehicle_description)/meshes/wheel.dae" scale="1 1 1" />
        </geometry>
      </visual>

      <collision>
        <geometry>
          <cylinder radius="${wheel_radius}" length="${wheel_thickness}" />
        </geometry>
      </collision>

      <inertial>
        <origin xyz="0 0 0" rpy="0 0 0"/>
        <mass value="${wheel_mass}"/>
        <inertia ixx="${wheel_mass/12*(3*wheel_radius*wheel_radius + wheel_thickness*wheel_thickness)}" ixy="0" ixz="0" iyy="${wheel_mass/12*(3*wheel_radius*wheel_radius + wheel_thickness*wheel_thickness)}" iyz="0" izz="${wheel_mass/2 * wheel_radius*wheel_radius}"/>
      </inertial>

    </link>
    <joint name="wheel_${name}_joint" type="continuous" >
      <parent link="base_link" />
      <child link="wheel_${name}" />
      <origin xyz="${x} ${y} ${z}" rpy="-1.57079632679 0 0" />
      <axis xyz="0 0 1" />
      <limit effort="-1.0" velocity="-1.0" />
    </joint>
  </xacro:macro>

  <xacro:macro name="front_wheel" params="name x y z flip" >
    <link name="wheel_${name}" >
      <visual>
        <origin xyz="0 0 0" rpy="1.57079632679 ${flip * pi} 0" />
        <geometry>
          <mesh filename="file://$(find gae_vehicle_description)/meshes/wheel.dae" scale="1 1 1" />
        </geometry>
      </visual>

      <collision>
        <geometry>
          <cylinder radius="${wheel_radius}" length="${wheel_thickness}" />
        </geometry>
      </collision>

      <inertial>
        <origin xyz="0 0 0" rpy="0 0 0"/>
        <mass value="${wheel_mass}"/>
        <inertia ixx="${wheel_mass/12*(3*wheel_radius*wheel_radius + wheel_thickness*wheel_thickness)}" ixy="0" ixz="0" iyy="${wheel_mass/12*(3*wheel_radius*wheel_radius + wheel_thickness*wheel_thickness)}" iyz="0" izz="${wheel_mass/2 * wheel_radius*wheel_radius}"/>
      </inertial>
    </link>

    <link name="steer_${name}" >
      <inertial>
        <origin xyz="-0.013054 -0.0295 0" rpy="0 0 0"/>
        <mass value="20.0"/>
        <inertia ixx="2" ixy="0" ixz="0" iyy="2" iyz="0" izz="2"/>
      </inertial>
    </link>

    <joint name="steer_${name}_joint" type="revolute" >
      <parent link="base_link" />
      <child link="steer_${name}" />
      <origin xyz="${x} ${y} ${z}" rpy="0 0 0" />
      <axis xyz="0 0 1" />
      <limit upper="0.6" lower="-0.6" effort="-1.0" velocity="-1.0" />
    </joint>

    <joint name="wheel_${name}_joint" type="continuous" >
      <parent link="steer_${name}" />
      <child link="wheel_${name}" />
      <origin xyz="0 0 0" rpy="-1.57079632679 0 0" />
      <axis xyz="0 0 1" />
      <limit effort="-1.0" velocity="-1.0" />
    </joint>
  </xacro:macro>

  <!-- <link name="base_footprint">
  </link> -->

  <link name="base_link">
    <visual>
      <origin xyz="0.19 0 -0.38" rpy="0 0 0" />
      <geometry>
        <mesh filename="file://$(find gae_vehicle_description)/meshes/gae_vehicle_body.dae" scale="1 1 1" />
      </geometry>
    </visual>
    <collision>
      <origin xyz="0.19 0 -0.38" rpy="0 0 0" />
      <geometry>
        <mesh filename="file://$(find gae_vehicle_description)/meshes/gae_vehicle_body.dae" scale="1 1 1" />
      </geometry>
    </collision>
    <inertial>
      <origin xyz="0 0 0" rpy="0 0 0"/>
      <mass value="${body_mass}"/>
      <inertia ixx="${body_mass/12 * (body_width*body_width + body_length*body_length)}" ixy="0" ixz="0" iyy="${body_mass/12 * (body_length*body_length + body_depth*body_depth)}" iyz="0" izz="${body_mass/12 * (body_width*body_width + body_depth*body_depth)}"/>
    </inertial>
  </link>
  
  <joint name="velodyne_base_mount_joint" type="fixed">
    <origin rpy="0 0 0" xyz="0.1 0 0.95"/>
    <parent link="base_link"/>
    <child link="lidar_front"/>
  </joint>
  
  <link name="lidar_front">
    <inertial>
      <mass value="0.83"/>
      <origin xyz="0 0 0.0"/>
      <inertia ixx="0.000908059425" ixy="0" ixz="0" iyy="0.000908059425" iyz="0" izz="0.0011049624"/>
    </inertial>
    <visual>
    	<origin xyz="0 0 0"/>
      <geometry>
        <mesh filename="file://$(find velodyne_description)/meshes/VLP16_base_1.dae" scale="1 1 1"/>
      </geometry>
    </visual>
    <visual>
    	<origin xyz="0 0 0"/>
      <geometry>
        <mesh filename="file://$(find velodyne_description)/meshes/VLP16_base_2.dae" scale="1 1 1" />
      </geometry>
    </visual>
    <collision>
      <origin rpy="0 0 0" xyz="0 0 0.0"/>
      <geometry>
        <cylinder length="0.0717" radius="0.0516"/>
      </geometry>
    </collision>
  </link>
  

  <joint name="velodyne_base_scan_joint" type="fixed">
    <origin rpy="0 0 0" xyz="0 0 0"/> 
    <parent link="lidar_front"/>
    <child link="velodyne"/>
  </joint>
  <link name="velodyne">
    <inertial>
      <mass value="0.01"/>
      <origin xyz="0 0 0"/>
      <inertia ixx="1e-7" ixy="0" ixz="0" iyy="1e-7" iyz="0" izz="1e-7"/>
    </inertial>
    <visual>
      <origin xyz="0 0 0"/>
      <geometry>
        <mesh filename="file://$(find velodyne_description)/meshes/VLP16_scan.dae" scale="1 1 1"/>
      </geometry>
    </visual>
  </link>

  <link name="imu_link">
  </link>

  <joint name="imu_joint" type="fixed">
    <origin xyz="0 0 0" rpy="0 0 0"/>
    <parent link="base_link"/>
    <child link="imu_link"/>
  </joint>

  <link name="gnss_front_right"/>
  <joint name="gnss_front_joint" type="fixed">
    <origin xyz="${half_wheelbase} 0 0.5" rpy="0 0 0"/>
    <parent link="base_link"/>
    <child link="gnss_front_right"/>
  </joint>

  <link name="gnss_rear_right"/>
  <joint name="gnss_rear_joint" type="fixed">
    <origin xyz="${-half_wheelbase} 0 0.5" rpy="0 0 0"/>
    <parent link="base_link"/>
    <child link="gnss_rear_right"/>
  </joint>

  <!-- <joint name="base_link_joint" type="fixed">
    <origin xyz="${half_wheelbase} 0 ${wheel_radius}" rpy="0 0 0"/>
    <parent link="base_footprint"/>
    <child link="base_link"/>
  </joint> -->

    <joint name="zed2_camera_center_joint" type="fixed">
      <parent link="base_link"/>
      <child link="zed2_camera_center"/>
      <origin xyz="0.195 0 0.91" rpy="0 0 0"/>
    </joint>

    <xacro:zed2 link_prefix="" 
                joint_prefix=""/>
    <xacro:zed2_gazebo robot_ns=""/>

  <xacro:rear_wheel name="rl" x="${-half_wheelbase}" y="${half_rear_track_width}" z="0" flip="1" />
  <xacro:rear_wheel name="rr" x="${-half_wheelbase}" y="${-half_rear_track_width}" z="0" flip="0" />
  <xacro:front_wheel name="fl" x="${half_wheelbase}" y="${half_front_track_width}" z="0" flip="1" />
  <xacro:front_wheel name="fr" x="${half_wheelbase}" y="${-half_front_track_width}" z="0" flip="0" />

  <xacro:property name="wheel_friction" value="1.75" />

  <gazebo reference="base_link" >
    <mu1>0.5</mu1>
    <mu2>0.5</mu2>
  </gazebo>

  <gazebo reference="wheel_fl" >
    <mu1>${wheel_friction}</mu1>
    <mu2>${wheel_friction}</mu2>
  </gazebo>

  <gazebo reference="wheel_fr" >
    <mu1>${wheel_friction}</mu1>
    <mu2>${wheel_friction}</mu2>
  </gazebo>

  <gazebo reference="wheel_rl" >
    <mu1>${wheel_friction}</mu1>
    <mu2>${wheel_friction}</mu2>
  </gazebo>

  <gazebo reference="wheel_rr" >
    <mu1>${wheel_friction}</mu1>
    <mu2>${wheel_friction}</mu2>
  </gazebo>
  
  <gazebo reference="velodyne">
    <sensor name="velodyne-VLP16" type="gpu_ray">
      <pose>0 0 0 0 0 0</pose>
      <visualize>false</visualize>
      <update_rate>10</update_rate>
      <ray>
        <scan>
          <horizontal>
            <samples>440</samples>
            <resolution>1</resolution>
            <min_angle>-3.141592653589793</min_angle>
            <max_angle>3.141592653589793</max_angle>
          </horizontal>
          <vertical>
            <samples>16</samples>
            <resolution>1</resolution>
            <min_angle>-0.2617993877991494</min_angle>
            <max_angle>
                  0.2617993877991494</max_angle>
          </vertical>
        </scan>
        <range>
          <min>0.3</min>
          <max>131.0</max>
          <resolution>0.001</resolution>
        </range>
        <noise>
          <type>gaussian</type>
          <mean>0.0</mean>
          <stddev>0.0</stddev>
        </noise>
      </ray>
      <plugin filename="libgazebo_ros_velodyne_laser.so" name="gazebo_ros_laser_controller">
        <topicName>/lidar_front/points_in</topicName>
        <frameName>lidar_front</frameName>
        <min_range>0.9</min_range>
        <max_range>130.0</max_range>
        <min_intensity>0.0</min_intensity>
        <gaussianNoise>0.008</gaussianNoise>
      </plugin>
    </sensor>
  </gazebo>

  <gazebo reference="gnss_front_right">
    <sensor type="gps" name="gps_front_sensor">
      <always_on>true</always_on>
      <update_rate>10</update_rate>
      <gps>
        <position_sensing>
          <horizontal><noise type="gaussian"><mean>0.0</mean><stddev>0.002</stddev></noise></horizontal>
          <vertical><noise type="gaussian"><mean>0.0</mean><stddev>0.002</stddev></noise></vertical>
        </position_sensing>
        <velocity_sensing>
          <horizontal><noise type="gaussian"><mean>0.0</mean><stddev>0.002</stddev></noise></horizontal>
        </velocity_sensing>
      </gps>
      <plugin filename="libgazebo_ros_gps_sensor.so" name="gps_front_plugin">
        <ros>
          <namespace>/sensing</namespace>
          <remapping>~/out:=gps_front/fix</remapping>
          <remapping>~/vel:=gps_front/vel</remapping>
        </ros>
        <frame_name>gnss_front_right</frame_name>
      </plugin>
    </sensor>
  </gazebo>

  <gazebo reference="gnss_rear_right">
    <sensor type="gps" name="gps_rear_sensor">
      <always_on>true</always_on>
      <update_rate>10</update_rate>
      <gps>
        <position_sensing>
          <horizontal><noise type="gaussian"><mean>0.0</mean><stddev>0.002</stddev></noise></horizontal>
          <vertical><noise type="gaussian"><mean>0.0</mean><stddev>0.002</stddev></noise></vertical>
        </position_sensing>
        <velocity_sensing>
          <horizontal><noise type="gaussian"><mean>0.0</mean><stddev>0.002</stddev></noise></horizontal>
        </velocity_sensing>
      </gps>
      <plugin filename="libgazebo_ros_gps_sensor.so" name="gps_rear_plugin">
        <ros>
          <namespace>/sensing</namespace>
          <remapping>~/out:=gps_rear/fix</remapping>
          <remapping>~/vel:=gps_rear/vel</remapping>
        </ros>
        <frame_name>gnss_rear_right</frame_name>
      </plugin>
    </sensor>
  </gazebo>

  <gazebo reference="imu_link">
    <gravity>true</gravity>
    <sensor type="imu" name="imu_sensor">
      <always_on>true</always_on>
      <update_rate>390.0</update_rate>
      <imu>
        <angular_velocity>
          <x>
            <noise type="gaussian">
              <mean>0.0</mean>
              <stddev>2e-4</stddev>
              <bias_mean>0.0000075</bias_mean>
              <bias_stddev>0.0000008</bias_stddev>
            </noise>
          </x>
          <y>
            <noise type="gaussian">
              <mean>0.0</mean>
              <stddev>2e-4</stddev>
              <bias_mean>0.0000075</bias_mean>
              <bias_stddev>0.0000008</bias_stddev>
            </noise>
          </y>
          <z>
            <noise type="gaussian">
              <mean>0.0</mean>
              <stddev>2e-4</stddev>
              <bias_mean>0.0000075</bias_mean>
              <bias_stddev>0.0000008</bias_stddev>
            </noise>
          </z>
        </angular_velocity>
        <linear_acceleration>
          <x>
            <noise type="gaussian">
              <mean>0.0</mean>
              <stddev>1.7e-2</stddev>
              <bias_mean>0.1</bias_mean>
              <bias_stddev>0.001</bias_stddev>
            </noise>
          </x>
          <y>
            <noise type="gaussian">
              <mean>0.0</mean>
              <stddev>1.7e-2</stddev>
              <bias_mean>0.1</bias_mean>
              <bias_stddev>0.001</bias_stddev>
            </noise>
          </y>
          <z>
            <noise type="gaussian">
              <mean>0.0</mean>
              <stddev>1.7e-2</stddev>
              <bias_mean>0.1</bias_mean>
              <bias_stddev>0.001</bias_stddev>
            </noise>
          </z>
        </linear_acceleration>
      </imu>
      <plugin name="imu_plugin" filename="libgazebo_ros_imu_sensor.so">
        <ros>
          <namespace>/sensing</namespace>
          <remapping>~/out:=imu/imu_raw</remapping>
        </ros>
        <initial_orientation_as_reference>false</initial_orientation_as_reference>
      </plugin>
    </sensor>
  </gazebo>

<joint name="ouster_base_mount_joint" type="fixed">
    <origin xyz="0.05 0 1.05" rpy="0 0 0"/>
    <parent link="base_link"/>
    <child link="ouster"/>
  </joint>

  <link name="ouster">
    <inertial>
      <mass value="0.5"/>
      <origin xyz="0 0 0.0365"/>
      <inertia ixx="0.0002411" ixy="0" ixz="0" iyy="0.0002411" iyz="0" izz="0.000264"/>
    </inertial>
    <visual>
      <origin xyz="0 0 0.0"/>
      <geometry>
        <cylinder radius="0.04" length="0.073"/>
      </geometry>
      <material name="ouster_black">
        <color rgba="0.1 0.1 0.1 1.0"/>
      </material>
    </visual>
    <collision>
      <origin xyz="0 0 0.0"/>
      <geometry>
        <cylinder radius="0.04" length="0.073"/>
      </geometry>
    </collision>
  </link>

  <gazebo reference="ouster">
    <sensor name="ouster-OS1-64" type="gpu_ray">
      <pose>0 0 0 0 0 0</pose>
      <visualize>false</visualize>
      <update_rate>10</update_rate>
      <ray>
        <scan>
          <horizontal>
            <samples>1024</samples>
            <resolution>1</resolution>
            <min_angle>-3.141592653589793</min_angle>
            <max_angle>3.141592653589793</max_angle>
          </horizontal>
          <vertical>
            <samples>64</samples>
            <resolution>1</resolution>
            <min_angle>-0.392699</min_angle> 
            <max_angle>0.392699</max_angle>
          </vertical>
        </scan>
        <range>
          <min>0.8</min>
          <max>120.0</max>
          <resolution>0.003</resolution>
        </range>
        <noise>
          <type>gaussian</type>
          <mean>0.0</mean>
          <stddev>0.008</stddev>
        </noise>
      </ray>
      <plugin filename="libgazebo_ros_velodyne_laser.so" name="gazebo_ros_ouster_controller">
        <topicName>/ouster/points</topicName>
        <frameName>ouster</frameName>
        <min_range>0.8</min_range>
        <max_range>120.0</max_range>
        <gaussianNoise>0.008</gaussianNoise>
      </plugin>
    </sensor>
  </gazebo>

</robot>
